<?xml version="1.0" encoding="utf-8"?>
<!-- This URDF was automatically created by SolidWorks to URDF Exporter! Originally created by Stephen Brawner (brawner@gmail.com) 
     Commit Version: 1.6.0-4-g7f85cfe  Build Version: 1.6.7995.38578
     For more information, please see http://wiki.ros.org/sw_urdf_exporter -->
<robot
  name="engineering_robot">
  <link
    name="robot_base">
    <inertial>
      <origin
        xyz="0.0061851 0.23193 -0.053228"
        rpy="0 0 0" />
      <mass
        value="22.186" />
      <inertia
        ixx="0.086122"
        ixy="0.00027171"
        ixz="-0.00022608"
        iyy="0.13784"
        iyz="0.00014595"
        izz="0.12207" />
    </inertial>
    <visual>
      <origin
        xyz="0 0 0"
        rpy="0 0 0" />
      <geometry>
        <mesh
          filename="package://engineering_robot/meshes/robot_base.STL" />
      </geometry>
      <material
        name="">
        <color
          rgba="1 1 1 1" />
      </material>
    </visual>
    <collision>
      <origin
        xyz="0 0 0"
        rpy="0 0 0" />
      <geometry>
        <mesh
          filename="package://engineering_robot/meshes/robot_base.STL" />
      </geometry>
    </collision>
  </link>
  <link
    name="J1_pris">
    <inertial>
      <origin
        xyz="0.025508 -0.0021843 -0.042762"
        rpy="0 0 0" />
      <mass
        value="1.0672" />
      <inertia
        ixx="0.00083452"
        ixy="-8.8251E-07"
        ixz="2.5901E-05"
        iyy="0.00086387"
        iyz="2.5424E-06"
        izz="0.0011539" />
    </inertial>
    <visual>
      <origin
        xyz="0 0 0"
        rpy="0 0 0" />
      <geometry>
        <mesh
          filename="package://engineering_robot/meshes/J1_pris.STL" />
      </geometry>
      <material
        name="">
        <color
          rgba="0.75294 0.75294 0.75294 1" />
      </material>
    </visual>
    <collision>
      <origin
        xyz="0 0 0"
        rpy="0 0 0" />
      <geometry>
        <mesh
          filename="package://engineering_robot/meshes/J1_pris.STL" />
      </geometry>
    </collision>
  </link>
  <joint
    name="J1_pris"
    type="prismatic">
    <origin
      xyz="-0.046 -0.1815 0.208"
      rpy="0 0 3.1416" />
    <parent
      link="robot_base" />
    <child
      link="J1_pris" />
    <axis
      xyz="0 0 -1" />
    <limit
      lower="0"
      upper="0.4"
      effort="0"
      velocity="0.0225" />
  </joint>
  <link
    name="J1_rotate">
    <inertial>
      <origin
        xyz="0.0034485 0.16712 0.010493"
        rpy="0 0 0" />
      <mass
        value="0.98991" />
      <inertia
        ixx="0.0009371"
        ixy="-8.1802E-06"
        ixz="2.0367E-07"
        iyy="0.00054043"
        iyz="9.0871E-06"
        izz="0.0013085" />
    </inertial>
    <visual>
      <origin
        xyz="0 0 0"
        rpy="0 0 0" />
      <geometry>
        <mesh
          filename="package://engineering_robot/meshes/J1_rotate.STL" />
      </geometry>
      <material
        name="">
        <color
          rgba="0.49804 0.49804 0.49804 1" />
      </material>
    </visual>
    <collision>
      <origin
        xyz="0 0 0"
        rpy="0 0 0" />
      <geometry>
        <mesh
          filename="package://engineering_robot/meshes/J1_rotate.STL" />
      </geometry>
    </collision>
  </link>
  <joint
    name="J1_rotate"
    type="revolute">
    <origin
      xyz="0 0 0"
      rpy="0 0 0" />
    <parent
      link="J1_pris" />
    <child
      link="J1_rotate" />
    <axis
      xyz="0 0 -1" />
    <limit
      lower="-3.14"
      upper="3.14"
      effort="0"
      velocity="3" />
  </joint>
  <link
    name="J2">
    <inertial>
      <origin
        xyz="-0.00573734592595407 0.043225485142845 0.0470279296086863"
        rpy="0 0 0" />
      <mass
        value="0.383011983841491" />
      <inertia
        ixx="0.000148028776265397"
        ixy="-4.86491073865014E-06"
        ixz="6.31806606790261E-08"
        iyy="0.000184807552922328"
        iyz="-4.84653975243787E-07"
        izz="0.000181665697679946" />
    </inertial>
    <visual>
      <origin
        xyz="0 0 0"
        rpy="0 0 0" />
      <geometry>
        <mesh
          filename="package://engineering_robot/meshes/J2.STL" />
      </geometry>
      <material
        name="">
        <color
          rgba="0.898039215686275 0.917647058823529 0.929411764705882 1" />
      </material>
    </visual>
    <collision>
      <origin
        xyz="0 0 0"
        rpy="0 0 0" />
      <geometry>
        <mesh
          filename="package://engineering_robot/meshes/J2.STL" />
      </geometry>
    </collision>
  </link>
  <joint
    name="J2"
    type="revolute">
    <origin
      xyz="0.004527 0.21888 0.043"
      rpy="0 0 -0.020679" />
    <parent
      link="J1_rotate" />
    <child
      link="J2" />
    <axis
      xyz="0 0 -1" />
    <limit
      lower="-3.14"
      upper="3.14"
      effort="0"
      velocity="3" />
  </joint>
  <link
    name="J3">
    <inertial>
      <origin
        xyz="-0.00666615456586628 0.0695663775980712 -0.0166594023403362"
        rpy="0 0 0" />
      <mass
        value="0.45196060079211" />
      <inertia
        ixx="0.00145013229782576"
        ixy="5.31382679486575E-07"
        ixz="-2.97314428264187E-07"
        iyy="0.000495105781411283"
        iyz="0.000451966378809907"
        izz="0.00097919283528486" />
    </inertial>
    <visual>
      <origin
        xyz="0 0 0"
        rpy="0 0 0" />
      <geometry>
        <mesh
          filename="package://engineering_robot/meshes/J3.STL" />
      </geometry>
      <material
        name="">
        <color
          rgba="0.898039215686275 0.917647058823529 0.929411764705882 1" />
      </material>
    </visual>
    <collision>
      <origin
        xyz="0 0 0"
        rpy="0 0 0" />
      <geometry>
        <mesh
          filename="package://engineering_robot/meshes/J3.STL" />
      </geometry>
    </collision>
  </link>
  <joint
    name="J3"
    type="revolute">
    <origin
      xyz="-0.014396 0.11107 0.059"
      rpy="0 -0.12124 0.12889" />
    <parent
      link="J2" />
    <child
      link="J3" />
    <axis
      xyz="0 -1 0" />
    <limit
      lower="-3.14"
      upper="3.14"
      effort="0"
      velocity="3" />
  </joint>
  <link
    name="J4_x">
    <inertial>
      <origin
        xyz="-0.0012584005113761 0.00167992518586291 0.00047767682143518"
        rpy="0 0 0" />
      <mass
        value="0.245833034470926" />
      <inertia
        ixx="0.000104922611477663"
        ixy="-4.99082449421437E-07"
        ixz="-1.85736980269919E-08"
        iyy="6.64077134638346E-05"
        iyz="-1.59394144342259E-07"
        izz="0.000112771537500298" />
    </inertial>
    <visual>
      <origin
        xyz="0 0 0"
        rpy="0 0 0" />
      <geometry>
        <mesh
          filename="package://engineering_robot/meshes/J4_x.STL" />
      </geometry>
      <material
        name="">
        <color
          rgba="0.898039215686275 0.917647058823529 0.929411764705882 1" />
      </material>
    </visual>
    <collision>
      <origin
        xyz="0 0 0"
        rpy="0 0 0" />
      <geometry>
        <mesh
          filename="package://engineering_robot/meshes/J4_x.STL" />
      </geometry>
    </collision>
  </link>
  <joint
    name="J4_x"
    type="revolute">
    <origin
      xyz="-0.0002 0.18972 -0.085"
      rpy="0.11366 0 0" />
    <parent
      link="J3" />
    <child
      link="J4_x" />
    <axis
      xyz="-1 0 0" />
    <limit
      lower="-3.14"
      upper="3.14"
      effort="0"
      velocity="3" />
  </joint>
  <link
    name="J4_y">
    <inertial>
      <origin
        xyz="-0.0012584 0.0016799 0.00047768"
        rpy="0 0 0" />
      <mass
        value="0.24583" />
      <inertia
        ixx="0.00010492"
        ixy="-4.9908E-07"
        ixz="-1.8574E-08"
        iyy="6.6408E-05"
        iyz="-1.5939E-07"
        izz="0.00011277" />
    </inertial>
    <visual>
      <origin
        xyz="0 0 0"
        rpy="0 0 0" />
      <geometry>
        <mesh
          filename="package://engineering_robot/meshes/J4_y.STL" />
      </geometry>
      <material
        name="">
        <color
          rgba="1 1 1 1" />
      </material>
    </visual>
    <collision>
      <origin
        xyz="0 0 0"
        rpy="0 0 0" />
      <geometry>
        <mesh
          filename="package://engineering_robot/meshes/J4_y.STL" />
      </geometry>
    </collision>
  </link>
  <joint
    name="J4_y"
    type="revolute">
    <origin
      xyz="0 0 0"
      rpy="0 0 0" />
    <parent
      link="J4_x" />
    <child
      link="J4_y" />
    <axis
      xyz="0 -1 0" />
    <limit
      lower="-10000"
      upper="10000"
      effort="0"
      velocity="3" />
  </joint>
  <link
    name="J5_end">
    <inertial>
      <origin
        xyz="-2.6706E-10 -0.0067571 1.0587E-11"
        rpy="0 0 0" />
      <mass
        value="0.10668" />
      <inertia
        ixx="3.616E-05"
        ixy="4.9507E-17"
        ixz="4.9508E-07"
        iyy="6.1762E-05"
        iyz="1.0429E-16"
        izz="3.784E-05" />
    </inertial>
    <visual>
      <origin
        xyz="0 0 0"
        rpy="0 0 0" />
      <geometry>
        <mesh
          filename="package://engineering_robot/meshes/J5_end.STL" />
      </geometry>
      <material
        name="">
        <color
          rgba="0 0 0 1" />
      </material>
    </visual>
    <collision>
      <origin
        xyz="0 0 0"
        rpy="0 0 0" />
      <geometry>
        <mesh
          filename="package://engineering_robot/meshes/J5_end.STL" />
      </geometry>
    </collision>
  </link>
  <joint
    name="J5_end"
    type="fixed">
    <origin
      xyz="0 0.1105 0"
      rpy="0 0 0" />
    <parent
      link="J4_y" />
    <child
      link="J5_end" />
    <axis
      xyz="0 0 0" />
  </joint>
</robot>