<?xml version="1.0" encoding="utf-8"?>
<!-- This URDF was automatically created by SolidWorks to URDF Exporter! Originally created by Stephen Brawner (brawner@gmail.com) 
     Commit Version: 1.6.0-4-g7f85cfe  Build Version: 1.6.7995.38578
     For more information, please see http://wiki.ros.org/sw_urdf_exporter -->
<robot
  name="engineering_robot">
  <link
    name="robot_base_link">
    <inertial>
      <origin
        xyz="0.15559 0.29313 0.010636"
        rpy="0 0 0" />
      <mass
        value="11.763" />
      <inertia
        ixx="0.14732"
        ixy="9.428E-05"
        ixz="-0.0072242"
        iyy="0.18275"
        iyz="3.5152E-05"
        izz="0.099271" />
    </inertial>
    <visual>
      <origin
        xyz="0 0 0"
        rpy="0 0 0" />
      <geometry>
        <mesh
          filename="package://engineering_robot/meshes/robot_base_link.STL" />
      </geometry>
      <material
        name="">
        <color
          rgba="0.49804 0.49804 0.49804 1" />
      </material>
    </visual>
    <collision>
      <origin
        xyz="0 0 0"
        rpy="0 0 0" />
      <geometry>
        <mesh
          filename="package://engineering_robot/meshes/robot_base_link.STL" />
      </geometry>
    </collision>
  </link>
  <link
    name="J1_link">
    <inertial>
      <origin
        xyz="0.017056 0 -0.053378"
        rpy="0 0 0" />
      <mass
        value="1.2292" />
      <inertia
        ixx="0.0022838"
        ixy="-8.5868E-19"
        ixz="2.5559E-06"
        iyy="0.0023771"
        iyz="-4.0594E-19"
        izz="0.0023915" />
    </inertial>
    <visual>
      <origin
        xyz="0 0 0"
        rpy="0 0 0" />
      <geometry>
        <mesh
          filename="package://engineering_robot/meshes/J1_link.STL" />
      </geometry>
      <material
        name="">
        <color
          rgba="1 1 1 1" />
      </material>
    </visual>
    <collision>
      <origin
        xyz="0 0 0"
        rpy="0 0 0" />
      <geometry>
        <mesh
          filename="package://engineering_robot/meshes/J1_link.STL" />
      </geometry>
    </collision>
  </link>
  <joint
    name="J1J"
    type="prismatic">
    <origin
      xyz="0.051 0.398 -0.041"
      rpy="0 0 0" />
    <parent
      link="robot_base_link" />
    <child
      link="J1_link" />
    <axis
      xyz="0 0 -1" />
    <limit
      lower="4"
      upper="0"
      effort="0"
      velocity="0.045" />
  </joint>
  <link
    name="J2_link">
    <inertial>
      <origin
        xyz="0.00068623 0.15908 0.010416"
        rpy="0 0 0" />
      <mass
        value="0.70346" />
      <inertia
        ixx="0.0051408"
        ixy="-1.8589E-05"
        ixz="3.2802E-06"
        iyy="0.00047532"
        iyz="5.4917E-05"
        izz="0.0049242" />
    </inertial>
    <visual>
      <origin
        xyz="0 0 0"
        rpy="0 0 0" />
      <geometry>
        <mesh
          filename="package://engineering_robot/meshes/J2_link.STL" />
      </geometry>
      <material
        name="">
        <color
          rgba="1 1 1 1" />
      </material>
    </visual>
    <collision>
      <origin
        xyz="0 0 0"
        rpy="0 0 0" />
      <geometry>
        <mesh
          filename="package://engineering_robot/meshes/J2_link.STL" />
      </geometry>
    </collision>
  </link>
  <joint
    name="J2J"
    type="revolute">
    <origin
      xyz="0 0 0"
      rpy="0 0 0" />
    <parent
      link="J1_link" />
    <child
      link="J2_link" />
    <axis
      xyz="0 0 -1" />
    <limit
      lower="-3.1415926"
      upper="3.1415926"
      effort="0"
      velocity="3.5" />
  </joint>
  <link
    name="J3_link">
    <inertial>
      <origin
        xyz="0.00014809 0.032998 0.044993"
        rpy="0 0 0" />
      <mass
        value="0.82034" />
      <inertia
        ixx="0.0017077"
        ixy="-3.9992E-06"
        ixz="-8.5896E-08"
        iyy="0.00081659"
        iyz="-1.9139E-05"
        izz="0.0016713" />
    </inertial>
    <visual>
      <origin
        xyz="0 0 0"
        rpy="0 0 0" />
      <geometry>
        <mesh
          filename="package://engineering_robot/meshes/J3_link.STL" />
      </geometry>
      <material
        name="">
        <color
          rgba="1 1 1 1" />
      </material>
    </visual>
    <collision>
      <origin
        xyz="0 0 0"
        rpy="0 0 0" />
      <geometry>
        <mesh
          filename="package://engineering_robot/meshes/J3_link.STL" />
      </geometry>
    </collision>
  </link>
  <joint
    name="J3J"
    type="revolute">
    <origin
      xyz="0.00034388 0.2195 0.066"
      rpy="0 0 -0.0050473" />
    <parent
      link="J2_link" />
    <child
      link="J3_link" />
    <axis
      xyz="0 0 -1" />
    <limit
      lower="-3.1415926"
      upper="3.1415926"
      effort="0"
      velocity="3.5" />
  </joint>
  <link
    name="J4_link">
    <inertial>
      <origin
        xyz="-0.00015933 0.10247 -0.028049"
        rpy="0 0 0" />
      <mass
        value="1.4198" />
      <inertia
        ixx="0.0070966"
        ixy="1.4199E-05"
        ixz="-4.8234E-06"
        iyy="0.0029838"
        iyz="0.0024997"
        izz="0.0062475" />
    </inertial>
    <visual>
      <origin
        xyz="0 0 0"
        rpy="0 0 0" />
      <geometry>
        <mesh
          filename="package://engineering_robot/meshes/J4_link.STL" />
      </geometry>
      <material
        name="">
        <color
          rgba="1 1 1 1" />
      </material>
    </visual>
    <collision>
      <origin
        xyz="0 0 0"
        rpy="0 0 0" />
      <geometry>
        <mesh
          filename="package://engineering_robot/meshes/J4_link.STL" />
      </geometry>
    </collision>
  </link>
  <joint
    name="J4J"
    type="revolute">
    <origin
      xyz="0.00046225 0.103 0.0457"
      rpy="0 0 -0.0044879" />
    <parent
      link="J3_link" />
    <child
      link="J4_link" />
    <axis
      xyz="0 -1 0" />
    <limit
      lower="-3.1415926"
      upper="3.1415926"
      effort="0"
      velocity="3.5" />
  </joint>
  <link
    name="J5_x_link">
    <inertial>
      <origin
        xyz="-1.9385E-05 1.7347E-17 -0.052831"
        rpy="0 0 0" />
      <mass
        value="0.042542" />
      <inertia
        ixx="4.1287E-05"
        ixy="5.5587E-22"
        ixz="4.3568E-08"
        iyy="4.1295E-05"
        iyz="1.2982E-21"
        izz="3.6413E-06" />
    </inertial>
    <visual>
      <origin
        xyz="0 0 0"
        rpy="0 0 0" />
      <geometry>
        <mesh
          filename="package://engineering_robot/meshes/J5_x_link.STL" />
      </geometry>
      <material
        name="">
        <color
          rgba="1 1 1 1" />
      </material>
    </visual>
    <collision>
      <origin
        xyz="0 0 0"
        rpy="0 0 0" />
      <geometry>
        <mesh
          filename="package://engineering_robot/meshes/J5_x_link.STL" />
      </geometry>
    </collision>
  </link>
  <joint
    name="J5_xJ"
    type="revolute">
    <origin
      xyz="-0.00049488 0.19759 -0.08712"
      rpy="0.0060187 0.0056803 0" />
    <parent
      link="J4_link" />
    <child
      link="J5_x_link" />
    <axis
      xyz="1 0 0" />
    <limit
      lower="-3.1415926"
      upper="3.1415926"
      effort="0"
      velocity="3.5" />
  </joint>
  <link
    name="J5_z_link">
    <inertial>
      <origin
        xyz="-1.9385E-05 1.7347E-17 -0.052831"
        rpy="0 0 0" />
      <mass
        value="0.042542" />
      <inertia
        ixx="4.1287E-05"
        ixy="5.5587E-22"
        ixz="4.3568E-08"
        iyy="4.1295E-05"
        iyz="1.2982E-21"
        izz="3.6413E-06" />
    </inertial>
    <visual>
      <origin
        xyz="0 0 0"
        rpy="0 0 0" />
      <geometry>
        <mesh
          filename="package://engineering_robot/meshes/J5_z_link.STL" />
      </geometry>
      <material
        name="">
        <color
          rgba="1 1 1 1" />
      </material>
    </visual>
    <collision>
      <origin
        xyz="0 0 0"
        rpy="0 0 0" />
      <geometry>
        <mesh
          filename="package://engineering_robot/meshes/J5_z_link.STL" />
      </geometry>
    </collision>
  </link>
  <joint
    name="J5_zJ"
    type="revolute">
    <origin
      xyz="0 0 0"
      rpy="0 0 0" />
    <parent
      link="J5_x_link" />
    <child
      link="J5_z_link" />
    <axis
      xyz="0 0 -1" />
    <limit
      lower="-3.1415926"
      upper="3.1415926"
      effort="0"
      velocity="3.5" />
  </joint>
  <link
    name="end_link">
    <inertial>
      <origin
        xyz="-4.6498E-06 -6.5542E-08 -0.018"
        rpy="0 0 0" />
      <mass
        value="0.088683" />
      <inertia
        ixx="2.6955E-05"
        ixy="-1.6846E-10"
        ixz="-2.0767E-10"
        iyy="2.6967E-05"
        iyz="-2.9274E-12"
        izz="3.477E-05" />
    </inertial>
    <visual>
      <origin
        xyz="0 0 0"
        rpy="0 0 0" />
      <geometry>
        <mesh
          filename="package://engineering_robot/meshes/end_link.STL" />
      </geometry>
      <material
        name="">
        <color
          rgba="1 1 1 1" />
      </material>
    </visual>
    <collision>
      <origin
        xyz="0 0 0"
        rpy="0 0 0" />
      <geometry>
        <mesh
          filename="package://engineering_robot/meshes/end_link.STL" />
      </geometry>
    </collision>
  </link>
  <joint
    name="end"
    type="fixed">
    <origin
      xyz="0 0 -0.137"
      rpy="-3.1416 0 0" />
    <parent
      link="J5_z_link" />
    <child
      link="end_link" />
    <axis
      xyz="0 0 0" />
  </joint>
</robot>