<?xml version="1.0" encoding="utf-8"?>
<!-- This URDF was automatically created by SolidWorks to URDF Exporter! Originally created by Stephen Brawner (brawner@gmail.com) 
     Commit Version: 1.6.0-4-g7f85cfe  Build Version: 1.6.7995.38578
     For more information, please see http://wiki.ros.org/sw_urdf_exporter -->
<robot
  name="engineering_robot">
  <link
    name="robot_base">
    <inertial>
      <origin
        xyz="0.0061850585644897 0.053228125930199 0.231928941982038"
        rpy="0 0 0" />
      <mass
        value="22.1862077008472" />
      <inertia
        ixx="0.0861221344984884"
        ixy="0.000226077590199201"
        ixz="0.00027171304963239"
        iyy="0.122067629093959"
        iyz="-0.000145945046806605"
        izz="0.137841741360346" />
    </inertial>
    <visual>
      <origin
        xyz="0 0 0"
        rpy="0 0 0" />
      <geometry>
        <mesh
          filename="package://engineering_robot/meshes/robot_base.STL" />
      </geometry>
      <material
        name="">
        <color
          rgba="1 1 1 1" />
      </material>
    </visual>
    <collision>
      <origin
        xyz="0 0 0"
        rpy="0 0 0" />
      <geometry>
        <mesh
          filename="package://engineering_robot/meshes/robot_base.STL" />
      </geometry>
    </collision>
  </link>
  <link
    name="J1_pris">
    <inertial>
      <origin
        xyz="0.0194665902809515 -0.0023335177595844 -0.0425273882163134"
        rpy="0 0 0" />
      <mass
        value="0.91288340947747" />
      <inertia
        ixx="0.000819887066916551"
        ixy="-8.83731445410227E-07"
        ixz="2.59007936258004E-05"
        iyy="0.000854066025906899"
        iyz="2.54241980276259E-06"
        izz="0.00113713465380161" />
    </inertial>
    <visual>
      <origin
        xyz="0 0 0"
        rpy="0 0 0" />
      <geometry>
        <mesh
          filename="package://engineering_robot/meshes/J1_pris.STL" />
      </geometry>
      <material
        name="">
        <color
          rgba="1 1 1 1" />
      </material>
    </visual>
    <collision>
      <origin
        xyz="0 0 0"
        rpy="0 0 0" />
      <geometry>
        <mesh
          filename="package://engineering_robot/meshes/J1_pris.STL" />
      </geometry>
    </collision>
  </link>
  <joint
    name="J1_pris_"
    type="prismatic">
    <origin
      xyz="-0.046 -0.1815 0.208"
      rpy="0 0 3.1416" />
    <parent
      link="robot_base" />
    <child
      link="J1_pris" />
    <axis
      xyz="0 0 -1" />
    <limit
      lower="-0.4"
      upper="0"
      effort="0"
      velocity="0.0225" />
  </joint>
  <link
    name="J1_rotate">
    <inertial>
      <origin
        xyz="0.00344845225870874 0.167124673552664 0.0104930612944998"
        rpy="0 0 0" />
      <mass
        value="0.989907036021585" />
      <inertia
        ixx="0.000937103570215255"
        ixy="-8.18023004581994E-06"
        ixz="2.03668858594027E-07"
        iyy="0.000540431879576359"
        iyz="9.08713227453938E-06"
        izz="0.00130847936953381" />
    </inertial>
    <visual>
      <origin
        xyz="0 0 0"
        rpy="0 0 0" />
      <geometry>
        <mesh
          filename="package://engineering_robot/meshes/J1_rotate.STL" />
      </geometry>
      <material
        name="">
        <color
          rgba="0.847058823529412 0.847058823529412 0.847058823529412 1" />
      </material>
    </visual>
    <collision>
      <origin
        xyz="0 0 0"
        rpy="0 0 0" />
      <geometry>
        <mesh
          filename="package://engineering_robot/meshes/J1_rotate.STL" />
      </geometry>
    </collision>
  </link>
  <joint
    name="J1_rotate_"
    type="revolute">
    <origin
      xyz="0 0 0"
      rpy="0 0 0" />
    <parent
      link="J1_pris" />
    <child
      link="J1_rotate" />
    <axis
      xyz="0 0 -1" />
    <limit
      lower="-3.14"
      upper="3.14"
      effort="0"
      velocity="3.0" />
  </joint>
  <link
    name="J2">
    <inertial>
      <origin
        xyz="-0.00479104788022719 0.0405042727022246 0.0474416018256969"
        rpy="0 0 0" />
      <mass
        value="0.47390104289524" />
      <inertia
        ixx="0.000341030410756508"
        ixy="-8.73081010936961E-07"
        ixz="2.06944368423626E-07"
        iyy="0.000233623673436517"
        iyz="-5.68139857721653E-06"
        izz="0.00032661740738155" />
    </inertial>
    <visual>
      <origin
        xyz="0 0 0"
        rpy="0 0 0" />
      <geometry>
        <mesh
          filename="package://engineering_robot/meshes/J2.STL" />
      </geometry>
      <material
        name="">
        <color
          rgba="0.898039215686275 0.917647058823529 0.929411764705882 1" />
      </material>
    </visual>
    <collision>
      <origin
        xyz="0 0 0"
        rpy="0 0 0" />
      <geometry>
        <mesh
          filename="package://engineering_robot/meshes/J2.STL" />
      </geometry>
    </collision>
  </link>
  <joint
    name="J2_"
    type="revolute">
    <origin
      xyz="0.004527 0.21888 0.043"
      rpy="0 0 -0.020679" />
    <parent
      link="J1_rotate" />
    <child
      link="J2" />
    <axis
      xyz="0 0 -1" />
    <limit
      lower="-3.14"
      upper="3.14"
      effort="0"
      velocity="3.0" />
  </joint>
  <link
    name="J3">
    <inertial>
      <origin
        xyz="-0.00666615456430499 0.0695663776012048 -0.0166594023425924"
        rpy="0 0 0" />
      <mass
        value="0.451960600792109" />
      <inertia
        ixx="0.00145013229782576"
        ixy="5.31382679486246E-07"
        ixz="-2.97314428263501E-07"
        iyy="0.000495105781411283"
        iyz="0.000451966378809908"
        izz="0.00097919283528486" />
    </inertial>
    <visual>
      <origin
        xyz="0 0 0"
        rpy="0 0 0" />
      <geometry>
        <mesh
          filename="package://engineering_robot/meshes/J3.STL" />
      </geometry>
      <material
        name="">
        <color
          rgba="0.898039215686275 0.917647058823529 0.929411764705882 1" />
      </material>
    </visual>
    <collision>
      <origin
        xyz="0 0 0"
        rpy="0 0 0" />
      <geometry>
        <mesh
          filename="package://engineering_robot/meshes/J3.STL" />
      </geometry>
    </collision>
  </link>
  <joint
    name="J3_"
    type="revolute">
    <origin
      xyz="-0.014396 0.11107 0.059"
      rpy="0 -0.12124 0.12889" />
    <parent
      link="J2" />
    <child
      link="J3" />
    <axis
      xyz="0 -1 0" />
    <limit
      lower="-3.14"
      upper="3.14"
      effort="0"
      velocity="3.0" />
  </joint>
  <link
    name="J4_x">
    <inertial>
      <origin
        xyz="-0.00125840050985948 0.0016799251887325 0.000477676818880196"
        rpy="0 0 0" />
      <mass
        value="0.245833034470928" />
      <inertia
        ixx="0.000104922611477663"
        ixy="-4.99082449421971E-07"
        ixz="-1.85736980271737E-08"
        iyy="6.64077134638348E-05"
        iyz="-1.59394144342606E-07"
        izz="0.000112771537500298" />
    </inertial>
    <visual>
      <origin
        xyz="0 0 0"
        rpy="0 0 0" />
      <geometry>
        <mesh
          filename="package://engineering_robot/meshes/J4_x.STL" />
      </geometry>
      <material
        name="">
        <color
          rgba="0.898039215686275 0.917647058823529 0.929411764705882 1" />
      </material>
    </visual>
    <collision>
      <origin
        xyz="0 0 0"
        rpy="0 0 0" />
      <geometry>
        <mesh
          filename="package://engineering_robot/meshes/J4_x.STL" />
      </geometry>
    </collision>
  </link>
  <joint
    name="J4_x_"
    type="revolute">
    <origin
      xyz="-0.0002 0.18972 -0.085"
      rpy="0.11366 0 0" />
    <parent
      link="J3" />
    <child
      link="J4_x" />
    <axis
      xyz="-1 0 0" />
    <limit
      lower="-3.14"
      upper="3.14"
      effort="0"
      velocity="3.0" />
  </joint>
  <link
    name="J4_y">
    <inertial>
      <origin
        xyz="-0.00125840050985948 0.0016799251887325 0.000477676818880141"
        rpy="0 0 0" />
      <mass
        value="0.245833034470928" />
      <inertia
        ixx="0.000104922611477663"
        ixy="-4.99082449421973E-07"
        ixz="-1.85736980271726E-08"
        iyy="6.64077134638348E-05"
        iyz="-1.59394144342605E-07"
        izz="0.000112771537500298" />
    </inertial>
    <visual>
      <origin
        xyz="0 0 0"
        rpy="0 0 0" />
      <geometry>
        <mesh
          filename="package://engineering_robot/meshes/J4_y.STL" />
      </geometry>
      <material
        name="">
        <color
          rgba="1 1 1 1" />
      </material>
    </visual>
    <collision>
      <origin
        xyz="0 0 0"
        rpy="0 0 0" />
      <geometry>
        <mesh
          filename="package://engineering_robot/meshes/J4_y.STL" />
      </geometry>
    </collision>
  </link>
  <joint
    name="J4_y_"
    type="revolute">
    <origin
      xyz="0 0 0"
      rpy="0 0 0" />
    <parent
      link="J4_x" />
    <child
      link="J4_y" />
    <axis
      xyz="0 -1 0" />
    <limit
      lower="-1.57"
      upper="1.57"
      effort="0"
      velocity="3.0" />
  </joint>
  <link
    name="J5_end">
    <inertial>
      <origin
        xyz="-2.65546112876436E-10 -0.00675708142560449 8.00104427156612E-12"
        rpy="0 0 0" />
      <mass
        value="0.106684158826586" />
      <inertia
        ixx="3.61598059282278E-05"
        ixy="4.95022995034358E-17"
        ixz="4.95084127780013E-07"
        iyy="6.17621391328186E-05"
        iyz="1.04286696465949E-16"
        izz="3.78396197137029E-05" />
    </inertial>
    <visual>
      <origin
        xyz="0 0 0"
        rpy="0 0 0" />
      <geometry>
        <mesh
          filename="package://engineering_robot/meshes/J5_end.STL" />
      </geometry>
      <material
        name="">
        <color
          rgba="0 0 0 1" />
      </material>
    </visual>
    <collision>
      <origin
        xyz="0 0 0"
        rpy="0 0 0" />
      <geometry>
        <mesh
          filename="package://engineering_robot/meshes/J5_end.STL" />
      </geometry>
    </collision>
  </link>
  <joint
    name="J5_end_"
    type="fixed">
    <origin
      xyz="0 0.1105 0"
      rpy="0 0 0" />
    <parent
      link="J4_y" />
    <child
      link="J5_end" />
    <axis
      xyz="0 0 0" />
  </joint>
</robot>