<?xml version="1.0" encoding="utf-8"?>
<!-- This URDF was automatically created by SolidWorks to URDF Exporter! Originally created by Stephen Brawner (brawner@gmail.com) 
     Commit Version: 1.6.0-4-g7f85cfe  Build Version: 1.6.7995.38578
     For more information, please see http://wiki.ros.org/sw_urdf_exporter -->
<robot
  name="example_robot_model">
  <link
    name="robot_base">
    <inertial>
      <origin
        xyz="0.00022169 -0.00028617 0.080329"
        rpy="0 0 0" />
      <mass
        value="4.4563" />
      <inertia
        ixx="0.023017"
        ixy="6.6589E-05"
        ixz="-7.0844E-06"
        iyy="0.018672"
        iyz="-0.00020968"
        izz="0.020191" />
    </inertial>
    <visual>
      <origin
        xyz="0 0 0"
        rpy="0 0 0" />
      <geometry>
        <mesh
          filename="package://example_robot_model/meshes/base.STL" />
      </geometry>
      <material
        name="">
        <color
          rgba="1 1 1 1" />
      </material>
    </visual>
    <collision>
      <origin
        xyz="0 0 0"
        rpy="0 0 0" />
      <geometry>
        <mesh
          filename="package://example_robot_model/meshes/base.STL" />
      </geometry>
    </collision>
  </link>
  <link
    name="r1">
    <inertial>
      <origin
        xyz="-0.0034411 -0.011433 0.077323"
        rpy="0 0 0" />
      <mass
        value="2.2514" />
      <inertia
        ixx="0.010774"
        ixy="-0.0003777"
        ixz="0.00021921"
        iyy="0.0083649"
        iyz="0.001428"
        izz="0.0046817" />
    </inertial>
    <visual>
      <origin
        xyz="0 0 0"
        rpy="0 0 0" />
      <geometry>
        <mesh
          filename="package://example_robot_model/meshes/r1.STL" />
      </geometry>
      <material
        name="">
        <color
          rgba="1 1 1 1" />
      </material>
    </visual>
    <collision>
      <origin
        xyz="0 0 0"
        rpy="0 0 0" />
      <geometry>
        <mesh
          filename="package://example_robot_model/meshes/r1.STL" />
      </geometry>
    </collision>
  </link>
  <joint
    name="r1"
    type="revolute">
    <origin
      xyz="0 0.017617 0.198"
      rpy="0 0 0" />
    <parent
      link="robot_base" />
    <child
      link="r1" />
    <axis
      xyz="0 0 -1" />
    <limit
      lower="-3.14"
      upper="3.14"
      effort="0"
      velocity="0.1" />
  </joint>
  <link
    name="r2">
    <inertial>
      <origin
        xyz="0.082259 -0.0072267 0.05219"
        rpy="0 0 0" />
      <mass
        value="0.22817" />
      <inertia
        ixx="0.00051338"
        ixy="0.00014117"
        ixz="-3.4423E-06"
        iyy="0.0018843"
        iyz="9.5466E-07"
        izz="0.0021562" />
    </inertial>
    <visual>
      <origin
        xyz="0 0 0"
        rpy="0 0 0" />
      <geometry>
        <mesh
          filename="package://example_robot_model/meshes/r2.STL" />
      </geometry>
      <material
        name="">
        <color
          rgba="1 1 1 1" />
      </material>
    </visual>
    <collision>
      <origin
        xyz="0 0 0"
        rpy="0 0 0" />
      <geometry>
        <mesh
          filename="package://example_robot_model/meshes/r2.STL" />
      </geometry>
    </collision>
  </link>
  <joint
    name="j2"
    type="revolute">
    <origin
      xyz="-0.070289 -0.0229 0.171"
      rpy="-1.5708 0 -1.7231" />
    <parent
      link="r1" />
    <child
      link="r2" />
    <axis
      xyz="0 0 -1" />
    <limit
      lower="-3.14"
      upper="3.14"
      effort="0"
      velocity="0.1" />
  </joint>
  <link
    name="r3">
    <inertial>
      <origin
        xyz="0.058716 0.035899 0.05825"
        rpy="0 0 0" />
      <mass
        value="0.93769" />
      <inertia
        ixx="0.0021447"
        ixy="-0.0015193"
        ixz="-3.09E-18"
        iyy="0.0033451"
        iyz="-2.5765E-18"
        izz="0.0054072" />
    </inertial>
    <visual>
      <origin
        xyz="0 0 0"
        rpy="0 0 0" />
      <geometry>
        <mesh
          filename="package://example_robot_model/meshes/r3.STL" />
      </geometry>
      <material
        name="">
        <color
          rgba="1 1 1 1" />
      </material>
    </visual>
    <collision>
      <origin
        xyz="0 0 0"
        rpy="0 0 0" />
      <geometry>
        <mesh
          filename="package://example_robot_model/meshes/r3.STL" />
      </geometry>
    </collision>
  </link>
  <joint
    name="j3"
    type="revolute">
    <origin
      xyz="0.17132 -0.014791 0.0055"
      rpy="0 0 0" />
    <parent
      link="r2" />
    <child
      link="r3" />
    <axis
      xyz="0 0 1" />
    <limit
      lower="-3.14"
      upper="3.14"
      effort="0"
      velocity="0" />
  </joint>
  <link
    name="r4">
    <inertial>
      <origin
        xyz="0.0265274515322492 -0.0284825849452257 0.0582476325711433"
        rpy="0 0 0" />
      <mass
        value="0.0747165876109567" />
      <inertia
        ixx="0.000239910336622906"
        ixy="-1.94921937076665E-05"
        ixz="-1.52421239463864E-09"
        iyy="0.000169514108857499"
        iyz="-8.30329263950967E-09"
        izz="0.000286517576861869" />
    </inertial>
    <visual>
      <origin
        xyz="0 0 0"
        rpy="0 0 0" />
      <geometry>
        <mesh
          filename="package://example_robot_model/meshes/r4.STL" />
      </geometry>
      <material
        name="">
        <color
          rgba="1 1 1 1" />
      </material>
    </visual>
    <collision>
      <origin
        xyz="0 0 0"
        rpy="0 0 0" />
      <geometry>
        <mesh
          filename="package://example_robot_model/meshes/r4.STL" />
      </geometry>
    </collision>
  </link>
  <joint
    name="j4"
    type="revolute">
    <origin
      xyz="0.11682 0.079683 0"
      rpy="0 0 0" />
    <parent
      link="r3" />
    <child
      link="r4" />
    <axis
      xyz="0 0 1" />
    <limit
      lower="-3.14"
      upper="3.14"
      effort="0"
      velocity="0" />
  </joint>
  <link
    name="r7">
    <inertial>
      <origin
        xyz="-0.000934941530290112 0.000461701815751586 0.0778843256649208"
        rpy="0 0 0" />
      <mass
        value="0.0980668668025426" />
      <inertia
        ixx="0.000272206456158683"
        ixy="2.56679630671344E-06"
        ixz="4.75133925140486E-06"
        iyy="0.000276169042376363"
        iyz="-2.35098077285761E-06"
        izz="0.000196073350290787" />
    </inertial>
    <visual>
      <origin
        xyz="0 0 0"
        rpy="0 0 0" />
      <geometry>
        <mesh
          filename="package://example_robot_model/meshes/r7.STL" />
      </geometry>
      <material
        name="">
        <color
          rgba="1 1 1 1" />
      </material>
    </visual>
    <collision>
      <origin
        xyz="0 0 0"
        rpy="0 0 0" />
      <geometry>
        <mesh
          filename="package://example_robot_model/meshes/r7.STL" />
      </geometry>
    </collision>
  </link>
  <joint
    name="j7"
    type="revolute">
    <origin
      xyz="0.053525 -0.071016 0.05825"
      rpy="1.5708 -0.32444 1.0968" />
    <parent
      link="r4" />
    <child
      link="r7" />
    <axis
      xyz="0 0 -1" />
    <limit
      lower="-3.14"
      upper="3.14"
      effort="0"
      velocity="0" />
  </joint>
  <link
    name="r5">
    <inertial>
      <origin
        xyz="0.0621816041243616 0.0381812779709092 0.0552499999999984"
        rpy="0 0 0" />
      <mass
        value="0.568071054532122" />
      <inertia
        ixx="0.000931848672002571"
        ixy="-0.000925927961725504"
        ixz="-1.00559751498031E-17"
        iyy="0.00177392072389187"
        iyz="1.30375311241382E-17"
        izz="0.00268446673134948" />
    </inertial>
    <visual>
      <origin
        xyz="0 0 0"
        rpy="0 0 0" />
      <geometry>
        <mesh
          filename="package://example_robot_model/meshes/r5.STL" />
      </geometry>
      <material
        name="">
        <color
          rgba="1 1 1 1" />
      </material>
    </visual>
    <collision>
      <origin
        xyz="0 0 0"
        rpy="0 0 0" />
      <geometry>
        <mesh
          filename="package://example_robot_model/meshes/r5.STL" />
      </geometry>
    </collision>
  </link>
  <joint
    name="j5"
    type="revolute">
    <origin
      xyz="0.024908 0.04932 0.066521"
      rpy="1.5708 -1.119 -0.4585" />
    <parent
      link="r7" />
    <child
      link="r5" />
    <axis
      xyz="0 0 -1" />
    <limit
      lower="-3.14"
      upper="3.14"
      effort="0"
      velocity="0" />
  </joint>
  <link
    name="r6">
    <inertial>
      <origin
        xyz="0.00150705127878992 0.00076752718745321 0.0544935023425193"
        rpy="0 0 0" />
      <mass
        value="0.0629104379086854" />
      <inertia
        ixx="0.000104917016287193"
        ixy="-3.99449837078143E-07"
        ixz="2.48074610039235E-08"
        iyy="0.000105499715307443"
        iyz="1.55011515889934E-08"
        izz="0.000100890591773057" />
    </inertial>
    <visual>
      <origin
        xyz="0 0 0"
        rpy="0 0 0" />
      <geometry>
        <mesh
          filename="package://example_robot_model/meshes/r6.STL" />
      </geometry>
      <material
        name="">
        <color
          rgba="1 1 1 1" />
      </material>
    </visual>
    <collision>
      <origin
        xyz="0 0 0"
        rpy="0 0 0" />
      <geometry>
        <mesh
          filename="package://example_robot_model/meshes/r6.STL" />
      </geometry>
    </collision>
  </link>
  <joint
    name="j6"
    type="revolute">
    <origin
      xyz="0.12692 0.081805 0"
      rpy="0 0 -0.025816" />
    <parent
      link="r5" />
    <child
      link="r6" />
    <axis
      xyz="0 0 -1" />
    <limit
      lower="-3.14"
      upper="3.14"
      effort="0"
      velocity="0" />
  </joint>
  <link
    name="end">
    <inertial>
      <origin
        xyz="-1.66533453693773E-16 1.11022302462516E-16 0.0110000000000001"
        rpy="0 0 0" />
      <mass
        value="0.10512397337438" />
      <inertia
        ixx="4.42133911350252E-05"
        ixy="-7.6232965252887E-21"
        ixz="-1.18796370852416E-19"
        iyy="4.42133911350252E-05"
        iyz="4.44692297308508E-20"
        izz="7.99467817511838E-05" />
    </inertial>
    <visual>
      <origin
        xyz="0 0 0"
        rpy="0 0 0" />
      <geometry>
        <mesh
          filename="package://example_robot_model/meshes/end.STL" />
      </geometry>
      <material
        name="">
        <color
          rgba="1 1 1 1" />
      </material>
    </visual>
    <collision>
      <origin
        xyz="0 0 0"
        rpy="0 0 0" />
      <geometry>
        <mesh
          filename="package://example_robot_model/meshes/end.STL" />
      </geometry>
    </collision>
  </link>
  <joint
    name="j8"
    type="fixed">
    <origin
      xyz="0.0686209400707701 0.0349308829519625 0.0542587238405839"
      rpy="1.5707963267949 0.464140960692069 -1.09994197771995" />
    <parent
      link="r6" />
    <child
      link="end" />
    <axis
      xyz="0 0 0" />
  </joint>
</robot>